[0m15:30:19.653410 [debug] [MainThread]: Sending event: {'category': 'dbt', 'action': 'invocation', 'label': 'start', 'context': [<snowplow_tracker.self_describing_json.SelfDescribingJson object at 0x7f8b589b3850>, <snowplow_tracker.self_describing_json.SelfDescribingJson object at 0x7f8b5a8aec40>, <snowplow_tracker.self_describing_json.SelfDescribingJson object at 0x7f8b5a8be9a0>]}


============================== 15:30:19.657485 | 121166f7-daae-4cf6-989d-4c68e9b028f9 ==============================
[0m15:30:19.657485 [info ] [MainThread]: Running with dbt=1.7.3
[0m15:30:19.658086 [debug] [MainThread]: running dbt with arguments {'printer_width': '80', 'indirect_selection': 'eager', 'write_json': 'True', 'log_cache_events': 'False', 'partial_parse': 'True', 'cache_selected_only': 'False', 'warn_error': 'None', 'debug': 'False', 'profiles_dir': '/Users/levi.dasillva/.dbt', 'log_path': 'logs', 'version_check': 'True', 'fail_fast': 'False', 'use_colors': 'True', 'use_experimental_parser': 'False', 'no_print': 'None', 'quiet': 'False', 'warn_error_options': 'WarnErrorOptions(include=[], exclude=[])', 'introspect': 'True', 'static_parser': 'True', 'log_format': 'default', 'target_path': 'None', 'invocation_command': 'dbt init', 'send_anonymous_usage_stats': 'True'}
[0m15:30:19.658656 [warn ] [MainThread]: [ConfigFolderDirectory]: Unable to parse dict {'dir': PosixPath('/Users/levi.dasillva/.dbt')}
[0m15:30:19.658999 [info ] [MainThread]: Creating dbt configuration folder at 
[0m15:30:37.301242 [debug] [MainThread]: Starter project path: /Users/levi.dasillva/opt/anaconda3/lib/python3.9/site-packages/dbt/include/starter_project
[0m15:30:37.309641 [info ] [MainThread]: 
Your new dbt project "cosmosproject" was created!

For more information on how to configure the profiles.yml file,
please consult the dbt documentation here:

  https://docs.getdbt.com/docs/configure-your-profile

One more thing:

Need help? Don't hesitate to reach out to us via GitHub issues or on Slack:

  https://community.getdbt.com/

Happy modeling!

[0m15:30:37.310531 [info ] [MainThread]: Setting up your profile.
[0m16:45:19.838112 [error] [MainThread]: Encountered an error:

[0m16:45:19.845073 [error] [MainThread]: Traceback (most recent call last):
  File "/Users/levi.dasillva/opt/anaconda3/lib/python3.9/site-packages/dbt/cli/requires.py", line 90, in wrapper
    result, success = func(*args, **kwargs)
  File "/Users/levi.dasillva/opt/anaconda3/lib/python3.9/site-packages/dbt/cli/requires.py", line 75, in wrapper
    return func(*args, **kwargs)
  File "/Users/levi.dasillva/opt/anaconda3/lib/python3.9/site-packages/dbt/cli/main.py", line 515, in init
    results = task.run()
  File "/Users/levi.dasillva/opt/anaconda3/lib/python3.9/site-packages/dbt/task/init.py", line 344, in run
    self.setup_profile(profile_name)
  File "/Users/levi.dasillva/opt/anaconda3/lib/python3.9/site-packages/dbt/task/init.py", line 264, in setup_profile
    self.create_profile_from_target(adapter, profile_name=profile_name)
  File "/Users/levi.dasillva/opt/anaconda3/lib/python3.9/site-packages/dbt/task/init.py", line 181, in create_profile_from_target
    self.create_profile_from_profile_template(profile_template, profile_name)
  File "/Users/levi.dasillva/opt/anaconda3/lib/python3.9/site-packages/dbt/task/init.py", line 165, in create_profile_from_profile_template
    target = self.generate_target_from_input(prompts, initial_target)
  File "/Users/levi.dasillva/opt/anaconda3/lib/python3.9/site-packages/dbt/task/init.py", line 131, in generate_target_from_input
    target[key] = click.prompt(
  File "/Users/levi.dasillva/opt/anaconda3/lib/python3.9/site-packages/click/termui.py", line 164, in prompt
    value = prompt_func(prompt)
  File "/Users/levi.dasillva/opt/anaconda3/lib/python3.9/site-packages/click/termui.py", line 147, in prompt_func
    raise Abort() from None
click.exceptions.Abort

[0m16:45:19.866897 [debug] [MainThread]: Resource report: {"command_name": "init", "command_wall_clock_time": 4500.2524, "process_user_time": 3.327147, "process_kernel_time": 2.018597, "process_mem_max_rss": "169615360", "command_success": false, "process_in_blocks": "0", "process_out_blocks": "0"}
[0m16:45:19.868729 [debug] [MainThread]: Command `dbt init` failed at 16:45:19.868198 after 4500.25 seconds
[0m16:45:19.869434 [debug] [MainThread]: Sending event: {'category': 'dbt', 'action': 'invocation', 'label': 'end', 'context': [<snowplow_tracker.self_describing_json.SelfDescribingJson object at 0x7f8b589b3850>, <snowplow_tracker.self_describing_json.SelfDescribingJson object at 0x7f8b5b56f490>, <snowplow_tracker.self_describing_json.SelfDescribingJson object at 0x7f8b499b2a90>]}
[0m16:45:19.869995 [debug] [MainThread]: Flushing usage events
